# 에러(Error)

- JS에서 에러 객체는 error 발생 시 던져지는 thrown 객체 입니다. 코드 실행 중 발생한 예외를 나타내는 데 사용되며 에러 객체에는 예외에 관한 정보가 포함되어 있어 디버깅 및 오류 처리에 도움이 됩니다. error 가 발생하지 않아도 생성자로 직접 생성하여 thrown이 가능하기도 합니다.

```
const error1=new Error("Something wrong...😅"); // new Error()

console.log(typeof error1); //object 출력!
console.error(error1);
```

<br>

- Error 객체의 생성자 함수는 두 가지 형식을 가질 수 있습니다. 첫 번째 형식은 위와 같이 에러 메시지를 전달하는 것이고, 두 번째 형식은 에러 객체의 사용자 지정 프로퍼티를 설정하는 것입니다. 

- Error 객체는 name, message, stack 프로퍼티로 Error 객체에 대한 정보를 확인 할 수 있습니다.

```
const error2=new Error("Something wrong...😅",
	{cause:"몬가...몬가 잘못되고있음!"} // 두 번째 인자의 프로퍼티 key: cause , value: "몬가...몬가 잘못되고있음!"
);

console.error(error2);
console.log(error2.cause);

console.log(error2.name);
console.log(error2.message);
console.log(error2.stack);
```

- 또는 사용자가 의도적으로 throw 를 사용하여 사용자가 의도적으로 에러를 발생 시킬 수 있습니다.

> throw new Error("I don't Know What's problem...");

<br>

- 에러의 종류는 다음과 같이 나뉩니다.

```
주요에러

SyntaxError | 문법에 이상이 있을 때
TypeError | 주어진 명령에 적절한 자료형이 아닐 때
ReferenceError | 잘못된 값을 참조했을 때
RangeError | 유효한 범위를 벗어나는 숫자가 사용되었을 때
```

<br>

### 에러 핸들링(error handling)

- 에러 핸들링은 예외적인 상황을 처리하고 코드의 안정성을 유지하기 위한 중요한 부분입니다. 에러 핸들링은 코드 실행 중 발생한 예외를 감지하고 적절하게 대응하는 프로세스를 의미합니다. 에러에 대한 적절한 대응이 없을 때 프로그램이 종료될 수 있는 위험이 있기에 에러 핸들링은 꼭 필요합니다.

```
// 에러로 인한 프로그램 종료
console.log('에러 발생 전');

// ⚠️ 오류를 발생시키는 코드
(3).split(''); 

// 출력되지 않음
console.log('에러 발생 후');
// Uncaught TypeError: 3.split is not a function
```

<br>

### 자바스크립트의 에러 핸들링

- try-catch 문: 가장 일반적인 에러 핸들링 방법 중 하나입니다. try 블록 안에서 코드를 실행하고, 예외가 발생할 경우 catch 블록에서 예외를 처리합니다. 이를 통해 예외가 발생하더라도 프로그램의 흐름을 제어할 수 있습니다.

```
console.log('에러 발생 전');

try {
  (3).split('');

} catch (e) {
  console.error('🛑 에러!!', e);
}

console.log('에러 발생 후');
```

- 위 에러 코드에서 try...catch를 추가하여 에러 핸들링하는 코드입니다. try {...} 은 오류가 날 수 있는 구문을 감쌉니다. 이곳에서 발생한 에러는 프로그램을 멈추지 않습니다. catch (error) {...} 구문은 try 문 뒤에 사용하고, 에러 발생시 실행할 코드 포함합니다. 발생한 오류 객체를 인자로 받습니다.

- 위 코드를 실행 하였을 때 오류가 발생하긴 한 것을 확인할 수 있습니다. 하지만 프로그램이 종료되지 않고 우선 try(시도) 한 후 에러를 catch 하여 위 작성한 대로 에러를 반환 하는 것을 알 수 있습니다.

<br>

- try...catch...finally: 앞서 살펴본 try...catch 문에서 finally가 추가 되었습니다. finally 구문 안에 작성한 부분은 오류가 존재하던 안하던 무조건 실행되는 특징이 있습니다. 기본 예시코드를 예를 들어 자세히 알아보겠습니다.

```
function connect () { console.log('☀️', '통신 연결'); }
function disconnect () { console.log('🌙', '통신 연결 해제'); }
function sendArray (arr) { console.log('전송', arr); }

function sendStringAsArray (str) {
  connect();

  try {
    sendArray(str.split(''));
    return true;

  } catch (e) {
    console.error('🛑 에러!!', e);
    return false;

  } finally {
    // 💡 전송 성공 여부와 관계없이 연결은 끊어야 함
    disconnect();
    console.log('- - - - - - - -');
  }

  // ❓ 이곳에 넣는 것과 무엇이 다른가?
  // 아래로 대체하여 실행해 볼 것
  // disconnect();
  // console.log('- - - - - - - -');
}

['ABC', '가나다', 123, '123'].forEach(i => {
  console.log(
    sendStringAsArray(i) 
    ? '[성공]' : '[실패]', '\n\n'
  );
});
```

- sendStringAsArray 함수는 str을 인자로 받습니다. connect()를 실행하고, 받은 문자열을 split('') 하여 return 또는 error가 발생하면 cathc 하여 return 합니다. 이후 finally {...} 에서 전송 성공 여부와 관계 없이 disconnect() 후 "---" 를 출력 합니다.

- 배열안에는 Error 를 발생 시킬 수 있는 123( type: Number ) 가 존재합니다. 실행 시켜보면 예상한대로 "ABC", "가나다", 문자열의 split이 성공적으로 진행 되다가 123 숫자에서 `에러!! TypeError: str.split is not a function` 가 발생하는 것을 확인 할 수 있습니다. 이후 "123" 문자열 까지 성공을 return 한 후 프로그램이 종료 됩니다.

<br>

-  finally 가 오류가 생기든 말든 무조건 출력 되는 것이라면 try...catch 구문 뒤에 작성해도 되지 않나? 또는 있으나 마나 아닌가?, 라는 의문이 생길 수 있는데 한번 시험해보겠습니다.

```
function connect () { console.log('☀️', '통신 연결'); }
function disconnect () { console.log('🌙', '통신 연결 해제'); }
function sendArray (arr) { console.log('전송', arr); }

function sendStringAsArray (str) {
  connect();

  try {
    sendArray(str.split(''));
    return true;

  } catch (e) {
    console.error('🛑 에러!!', e);
    return false;

  } // finally 부분 삭제
   disconnect();
   console.log('- - - - - - - -');
}

['ABC', '가나다', 123, '123'].forEach(i => {
  console.log(
    sendStringAsArray(i) 
    ? '[성공]' : '[실패]', '\n\n'
  );
});
```

- 이전과 다르게 통신이 연결은 되지만, 연결 해제가 되지 않고 줄 바뀜 식별을 위해 작성한 ("-----") 부분도 출력되지 않음을 확인할 수 있습니다. 

- 함수에서 도중에 return 문을 만났을 시에 구문을 종료합니다. `[성공했을 때 cath(e) {...} 부분이 나오지 않는 것 처럼]` 그러나 finally 는 try 또는 catch 에서 return 을 만나더라도 반드시 실행 합니다. 

<br>

### 에러 버블링(error Bubbling)

- 이벤트 처리 중에 발생한 오류가 부모 요소를 거슬러 올라가면서 처리되는 메커니즘을 가리킵니다.(물방울이 수면위로 올라가는 원리와 비슷하게 동작)

```
// 에러 버블링의 예시 코드
function func1 () {
  throw new Error('에러');
}

function func2 () {
  func1();
}

function func3 () {
  func2();
}

function func4 () {
  try {
    func3();

  } catch (e) {
    console.error(e);
  }
  console.log('실행완료');
}

func4();
// 4 -> 3 -> 2 -> 1(예외 발생. 호출스택 거슬러올라가기) -> 2 -> 3 -> 4
```

- 위 코드를 살펴보면 func4를 실행하고 func4는 3을 3은 2를 호출하는 형태로 이벤트 버블링의 한 예시를 보여줍니다.

- func1 에서는 에러를 생성합니다. 에러가 생성 되었으니 func4의 catch(e) 를 실행 한 뒤 console.log('실행 완료') 를 끝으로 코드가 마무리 됩니다. 만약 반환 값 return 이 있을 때 "실행완료" 구문을 출력하고 싶다면 finally를 사용 할 수 있습니다.

<br>

### 엄격 모드(strict_mode)

-  ECMAScript 5(ES5)에서 도입된 자바스크립트의 기능 중 하나입니다. 이 모드를 활성화하면 더 엄격한 문법과 오류 검사가 수행되어 코드의 안전성을 향상시키고 일부 오류를 방지할 수 있습니다. 

- 기존에 허용되던, 문제를 유발할 수 있는 코드들에 오류를 발생시키게 됩니다. 엄격 모드를 활성화하는 방법은 전역 범위에서 "use strict"; 문자열을 추가하는 것입니다. 

> declared=1; // 암묵적으로 전역 var 키워드 변수로 선언 됩니다.

- 새로 고침 후 다시 실행 시켜봅시다.

```
"use strict";

declared=1;
```

- ReferenceError가 나오면서 잘못된 값을 참조 하였음을 알려줍니다. 엄격 모드는 함수 단위로만의 실행 또한 가능합니다(함수의 최상단에 작성할 것).

```
notDec1 = 1;

function strictFunc () {
'use strict';

 notDec2 = 2;
 console.log(notDec2);
}

console.log(notDec1); // 1
strictFunc(); // Uncaught ReferenceError: notDec2 is not defined
```

<br>

### 옵셔널 체이닝(Optional Chaining)

- 코드를 작성하다보면 네트워크 요청 등, 어떤 값이 들어올지 알 수 없는 상황이 발생할 때가 있습니다. 이 때 옵셔널 체이닝을 통해 에러 핸들링이 가능합니다. (중첩된 구조의 하위 요소 접근시 발생하는 에러 Cannot read property 'x' of undefined 를 방지 해줍니다.)

- 옵셔널 체이닝은 물음표(?) 연산자를 사용하여 객체의 속성이나 메서드에 접근할 때 해당 속성이나 메서드가 존재하는지 먼저 확인합니다. 만약 해당 속성이나 메서드가 존재하지 않으면 undefined를 반환하고, 에러를 발생시키지 않습니다. 있을지 없을지 모르는 것으로부터 값을 읽거나 실행할 때 사용하기 유용합니다.

```
// 최소 undefined 최대 `{prop1:{prop2:{prop3:'성공!'}}}` 까지 반환하는 함수

const rand = () => Math.random() < 0.75;

const notSure = () => rand() ? {
  prop1: rand() ? {
    prop2: rand() ? {
      prop3: rand() ? '성공!' : undefined
    } : undefined
  } : undefined
} : undefined;

// 위 코드 작성 후 아래 실행문을 반복해보자.
const result = notSure();
console.log(JSON.stringify(result));
```

- rand 함수의 경우 Math.random()의 값이 0.75보다 작다면 true 를 반환하는 함수 입니다(약 75% 정도의 확률). notSure 함수는 rand()의 값이 true 라면 그 다음 메서드를 실행 합니다. props1 => props2 => props3 => 성공

- 위 코드를 반복해서 실행문을 통해 출력 하였을 떄 결과 값이 제각각 인것을 확인 할 수 있습니다.

```
undefined
{}
{"prop1:{}"}
{"prop1":{"prop2":{}}}
{"prop1":{"prop2":{"prop3":"성공!"}}}
```

- 옵셔널 체이닝을 통해 true 일 때는 다음 메서드를 호출, false 라면 undefined를 출력하게 됩니다.

- 옵셔널 체이닝을 사용하지 않고 중첩 구조의 요소에 접근하기 위해 if() 조건문을 중첩하여 사용하거나, && 연산자를 사용, try...catch 구문 등을 사용할 수 있습니다.

- 위 예시 함수의 길이가 길지 않아 위 방법도 충분히 사용할 수 있지만, 길이가 길어질 수록 에러를 피하기 위해서 코드의 길이가 점점 더 길어질 것 입니다. 
